# 예외처리

## 1. 예외처리

<br>

---

### 1.1. 프로그램 오류

- 컴파일 에러 : 컴파일 시 발생하는 에러입니다.

  <br/>

- 런타임 에러 : 프로그래밍 오류로 인해 실행 시 발생하는 에러입니다.

  - Java 런타임 에러 1: 에러(error)

    - 프로그램 코드에 의해 수습될 수 없는 심각한 오류

  - Java 런타임 에러 2: 예외(exception)

    - 프로그램 코드에 의해서 수습될 수 있는 미약한 오류

  - 에러는 수정을 해야하고, 예외는 처리를 해야합니다

    <br/>

- 논리적 에러 : 실행 시 의도와 다르게 동작하면서 발생하는 에러입니다.

<br/>

<br/>

---

### 1.2. 예외처리

- 재귀호출을 하는 함수를 생성해보겠습니다.

```java
public static void recursive() {
    recursive();
}
```

> main 함수에서 recursive 함수를 실행시켜 보겠습니다.
>
> 아래와 같이 출력 됩니다.
>
> ![image-20231128133325309](https://raw.githubusercontent.com/wholeheartedness/image_repo/main/img/image-20231128133325309.png)
>
> 재귀함수를 멈출 코드가 작성되지 않아 스택오버플로우가 발생합니다.

<br/>

- 예외처리는 프로그램 실행 시 발생할 수 있는 예외의 발생에 대비한 코드를 작성하는 것을 의미 합니다
- Java의 예외 처리 단계는 아래와 같습니다.

- 프로그램의 비정상 종료를 막고, 정상적인 실행 상태를 유지할 수 있습니다.

![자바 예외(Throwable) :: Messi Lover](https://t1.daumcdn.net/cfile/tistory/99DF7E455EC3EDC638)

**💡[Unchecked Exception] RuntimeException의 종류 (대비가 가능한 단계)**

- NullPointerException: 잘못된 null 사용 (null의 메서드 호출 등)

- ArrayIndexOutOfBoundsException: 어떤 배열의 범위를 벗어나는 index 사용

- ArithmeticException: 0으로 나누는 등의 수학적 오류

  ➡️ unchecked Exception으로 JVM(컴파일러)가 처리하지 않습니다.

<br/>

**💡[Checked Exception] RuntimeException을 상속받지 않는 모든 예외의 종류 (대비가 불가능한 단계)**

- FileNotFoundException : 파일을 사용하려 하는데 파일이 존재하지 않을 때
- SQLException : 데이터베이스 사용 중 문제가 발생할 때
- 인자로 전달 된 (예측 / 제어 불가한) filename에 해당하는 파일이 없는 경우

<br/>

---

- 아래의 코드를 예시로 알아보겠습니다.

  ```java
  public static void main(String[] args) {
      Scanner sc = new Scanner(System.in);
      int a = sc.nextInt();
      int b = sc.nextInt();
      System.out.println(divide(a, b));
      System.out.println("Bye!");
      System.out.println("여기까지 실행됐습니다.");
  }
      // 두개의 정수를 받아 나누어서 정수 결과를 반환하는 정적 메서드
      public static int divide (int a, int b) {
          return a / b;
      }
  ```

  - int a나 int b에 0을 입력합니다.

    > 아래와 같이 출력 됩니다.
    >
    > Exception in thread "main" java.lang.ArithmeticException: / by zero
    > 	at D6Exception.Main.divide(Main.java:16)
    > 	at D6Exception.Main.main(Main.java:10)
    >
    > ![image-20231128115309943](https://raw.githubusercontent.com/wholeheartedness/image_repo/main/img/image-20231128115309943.png)
    >
    > 예외가 발생합니다.
    >
    > 프로그램이 끝까지 실행되지 못하고 중단됩니다.

<br/>

<br/>

---

<br/>

<br/>

## 2. Checked Exception

<br/>

**💡[Unchecked Exception] RuntimeException의 종류 (대비가 가능한 단계)**

- NullPointerException: 잘못된 null 사용 (null의 메서드 호출 등)

- ArrayIndexOutOfBoundsException: 어떤 배열의 범위를 벗어나는 index 사용

- ArithmeticException: 0으로 나누는 등의 수학적 오류

  ➡️ unchecked Exception으로 JVM(컴파일러)가 처리하지 않습니다.

---

### 2.1. try-catch

<br/>

#### 2.1.1. try-catch

- try ( <예외가 발생할 가능성이 있는 문장을 적습니다> )
- catch ( <발생했을 경우, 이를 처리하기 위한 문장을 적습니다)

```java
try { < 예외가 발생할 가능성이 있는 문장 >
    } catch ( <발생가능한에러클래스> <에러변수>) {
    <발생 가능한 에러가 발생했을 경우, 이를 처리하기 위한 문장>
} 
```

<br/>

- 예시코드에 적용해보겠습니다.

- 수학 연산의 에러 처리 Exception은 ArithmeticException을 사용합니다.

  ```java
  Scanner sc = new Scanner(System.in);
  int a = sc.nextInt();
  int b = sc.nextInt();
  try {
      System.out.println(divide(a, b));
      System.out.println("Bye!");
  } catch (ArithmeticException e) {
      System.out.println("Sorry, can't do that");
  }
      System.out.println("여기까지 실행됐습니다.");
  ```

  > 아래와 같이 출력 됩니다.
  >
  > ![image-20231128115218395](https://raw.githubusercontent.com/wholeheartedness/image_repo/main/img/image-20231128115218395.png)
  >
  > 예외 처리 된 실행문(try)를 뛰어 넘고 catch가 실행되고 try-catch 구문을 탈출하여 모든 구문이 실행되었습니다.
  >
  > 💡exit code 0 : 모든 것이 정상적으로 종료 됐음을 의미합니다

  <br/>

  - <에러명>.getMessage() 메서드를 사용하여 어떤 에러가 발생했는지 확인할 수 있습니다.

    ```java
    catch (ArithmeticException e) {
        System.out.println(e.getMessage());
    }
    ```

    > 아래와 같이 출력 됩니다.
    >
    > ![image-20231128115157939](https://raw.githubusercontent.com/wholeheartedness/image_repo/main/img/image-20231128115157939.png)

    <br/>

  - 이는 try-catch 구문에서 아래와 같이 사용됩니다.

    ```java
    try {
        System.out.println(divide(a, b));
        System.out.println("Bye!");
    } catch (ArithmeticException e) {
        System.out.println(String.format("Sorry, this happend: %s", e.getMessage()));
    }
    ```

    > 아래와 같이 출력 됩니다.
    >
    > ![image-20231128115405983](https://raw.githubusercontent.com/wholeheartedness/image_repo/main/img/image-20231128115405983.png)



<br/>

- try-catch 구문은 어떤 예외가 발생할 지 어느정도 알고 있는 상태에서 사용합니다.

  <br/>

  ---

#### 2.1.2. try-catch-finally

- try-catch에서 finally를 사용하여  예외 처리가 실행 됐든, 안됐든 명령을 수행할 수 있습니다.

- finally ( <정상 처리, 예외 처리와 관계 없이 실행할 문장을 적습니다> )

  ```java
  try { < 예외가 발생할 가능성이 있는 문장 >
      } catch ( <발생가능한에러클래스> <에러변수>) {
      <발생 가능한 에러가 발생했을 경우, 이를 처리하기 위한 문장>
  } finally { <정상/예외에 관계 없이 실행할 문장> }
  ```

  <br/>

- 예시 코드를 확인해보겠습니다.

- "Bye!" 출력을 예외 유무와 상관없이 마지막으로 출력하고자 합니다.

  ```java
  try {
      System.out.println(divide(a, b));
  } catch (ArithmeticException e) {
      System.out.println(String.format("Sorry, this happend: %s", e.getMessage()));
  } finally {
      System.out.println("Bye!");
  }
  ```

  > 아래와 같이 출력 됩니다.
  >
  > 10과 0을 입력했을 때
  >
  > ![image-20231128114602568](https://raw.githubusercontent.com/wholeheartedness/image_repo/main/img/image-20231128114602568.png)
  >
  > 4와 2를 입력했을 때
  >
  > ![image-20231128114637164](https://raw.githubusercontent.com/wholeheartedness/image_repo/main/img/image-20231128114637164.png)
  >
  > finally 구문이 두 상황 모두 정상 출력 됐습니다.

<br/>

- null이 인자로 주어졌을 때의 예외 처리를 알아보겠습니다.

  - API를 가지고 오는 과정(Call)에서  원시타입을 허용하지 않는 경우가 있습니다.
  - 변수가 아래와 같이 주어졌습니다.

  ```java
  Integer a = 10;
  Integer b = null;
  ```

  - 아래의 메서드를 수행하기 위해서는 매개변수로 int(원시타입)을 받아야 하는데 null이 들어가 Error가 발생합니다.

  ```java
  public static int divide (int a, int b) {
      return a / b;
  }
  ```

  > 아래와 같이 출력됩니다.
  > Exception in thread "main" java.lang.NullPointerException: Cannot invoke "java.lang.Integer.intValue()" because "b" is null
  > 	at D6Exception.Main.main(Main.java:18)
  >
  > ![image-20231128131112757](https://raw.githubusercontent.com/wholeheartedness/image_repo/main/img/image-20231128131112757.png)

  - 이 때도 catch를 사용하여 예외 처리를 해줍니다.
  - NullPointerExcepion을 사용합니다.

  ```java
  catch (NullPointerException e) {
      System.out.println("Null Point Exception");
  } 
  ```

  - 예외처리를 다중으로 할 수 있습니다.

  ```java
  catch (ArithmeticException e) {
      System.out.println(String.format("Sorry, this happend: %s", e.getMessage()));
  } catch (NullPointerException e) {
      System.out.println("Null Point Exception");
  } 
  ```

  - 예외 처리에 주어진 조건문을 한 곳에서 처리할 수 있습니다.
  - | 를 사용합니다.

  ```java
  catch (ArithmeticException  | NullPointerException e) {
  System.out.println(String.format("Sorry, this happend: %s", e.getMessage()));
          } 
  ```

  > 아래와 같이 출력 됩니다.
  >
  > ![image-20231128131729586](https://raw.githubusercontent.com/wholeheartedness/image_repo/main/img/image-20231128131729586.png)
  >
  > 예외 처리가 정상적으로 됐습니다.

  <br/>

  <br/>

---

### 2.2. throw

- Double을 0으로 나누면 에러가 아닌 Infinity가 출력 됩니다 (무한)

- 이 때는 사용자가 수동으로 예외처리 할 것을 지정해줘야 합니다.

- 새로운 예외 인스턴스인 throw new를 사용합니다.

  ```java
  throw new <발생가능한에러클래스> ("예외 처리 설명")
  ```

  <br/>

  ```java
  public static double divideToDouble(int a, int b) {
      if ( b== 0) {
          throw new ArithmeticException("Division by Zero");
      }
      return (double) a / b;
  }
  ```

  > 아래와 같이 출력 됩니다.
  >
  > ![image-20231128132630285](https://raw.githubusercontent.com/wholeheartedness/image_repo/main/img/image-20231128132630285.png)
  >
  > b == 0 일때 ArithmeticException 예외처리로 분류되었습니다. 

<br/>

<br/>

---

## 3. Unchecked Exception

<br/>

**💡[Checked Exception] RuntimeException을 상속받지 않는 모든 예외의 종류 (대비가 불가능한 단계)**

- FileNotFoundException : 파일을 사용하려 하는데 파일이 존재하지 않을 때

- SQLException : 데이터베이스 사용 중 문제가 발생할 때

- 인자로 전달 된 (예측 / 제어 불가한) filename에 해당하는 파일이 없는 경우

  ---

- RuntimeException을 상속받지 않는 Exception은 코드 단위에서 방지할 수 없기 때문에 예외 처리 과정에서 미리 컴파일러가 알려줍니다.

- 확인 후 코드 단위에서 예외처리를 어떻게든 선으로 해줍니다.

  ---

  

<br/>

- 아래 예시 코드를 알아보겠습니다.

  ```java
  public static void readFileContents(String filename) {
  File file = new File(filename);
   Scanner scanner = new Scanner(file);
  ```

  > main 메서드에서 함수를 실행하면 아래와 같이 출력 됩니다.
  >
  > java: unreported exception java.io.FileNotFoundException; must be caught or declared to be thrown
  >
  > ![image-20231128141602183](https://raw.githubusercontent.com/wholeheartedness/image_repo/main/img/image-20231128141602183.png)

  <br/>

  ```java
  public static void readFileContents(String filename) {
      File file = new File(filename);
      try {
          Scanner scanner = new Scanner(file);
          while (scanner.hasNextLine())
              System.out.println(scanner.nextLine());
      } catch (FileNotFoundException e) {
          System.out.println("File Not Found");
      }
  }
  ```

  - FileNotFoundException으로 예외 처리를 해줍니다.

    <br/>

  ---

  <br/>

  - 아래와 같이 처리해 줄 수도 있습니다.
  - 선언문에서 FileNotFoundException 예외를 던집니다.

  ```java
  public static void readFileThrows(String filename) throws FileNotFoundException {
      File file = new File(filename);
      Scanner scanner = new Scanner(file);
      while (scanner.hasNextLine())
          System.out.println(scanner.nextLine());
  }
  ```

  - 이 때는 main 메서드에서 try-catch를 처리해줍니다.

  ```java
  try {
      readFileThrows("file-not-exist");
  } catch (FileNotFoundException e) {
      System.out.println("File Not Found");
  }
  ```

  